{"content": {"suites": {"0": {"status": {"total_pass": 15, "total_skip": 0, "total_xpass": 0, "total_xfail": 0, "total_rerun": 0, "total_fail": 6, "total_error": 0}, "tests": {"0": {"status": "PASS", "message": "", "test_name": "test_1_SetupOs", "rerun": "0"}, "1": {"status": "PASS", "message": "", "test_name": "test_2_Login", "rerun": "0"}, "2": {"status": "PASS", "message": "", "test_name": "test_3_AksesMenu", "rerun": "0"}, "3": {"status": "PASS", "message": "", "test_name": "test_4_ClickButtonTambah", "rerun": "0"}, "4": {"status": "PASS", "message": "", "test_name": "test_5_InputBidangGiatja", "rerun": "0"}, "5": {"status": "PASS", "message": "", "test_name": "test_6_InputJenisKegiatanKerja", "rerun": "0"}, "6": {"status": "PASS", "message": "", "test_name": "test_7_namaKegiatan", "rerun": "0"}, "7": {"status": "PASS", "message": "", "test_name": "test_8_skalaKegiatan", "rerun": "0"}, "8": {"status": "PASS", "message": "", "test_name": "test_9_tanggalAwalKegiatan", "rerun": "0"}, "9": {"status": "PASS", "message": "", "test_name": "test_10_tanggalAkhirKegiatan", "rerun": "0"}, "10": {"status": "PASS", "message": "", "test_name": "test_12_lokasiKegiatan", "rerun": "0"}, "11": {"status": "PASS", "message": "", "test_name": "test_11_AreaKegiatan", "rerun": "0"}, "12": {"status": "PASS", "message": "", "test_name": "test_13_luas", "rerun": "0"}, "13": {"status": "PASS", "message": "", "test_name": "test_14_jumlahRuang", "rerun": "0"}, "14": {"status": "PASS", "message": "", "test_name": "test_15_sarana", "rerun": "0"}, "15": {"status": "FAIL", "message": "       NameError: name 'prasaranaFkr' is not defined\n       assert False\n", "test_name": "test_16_prasarana", "rerun": "0"}, "16": {"status": "FAIL", "message": "           ConnectionRefusedError: [Errno 61] Connection refused\n       urllib3.exceptions.NewConnectionError: <urllib3.connection.HTTPConnection object at 0x140851250>: Failed to establish a new connection: [Errno 61] Connection refused\n       urllib3.exceptions.MaxRetryError: HTTPConnectionPool(host='localhost', port=54091): Max retries exceeded with url: /session/6989a4b9db5e64b95268f36aa5d0a2f6/timeouts (Caused by NewConnectionError('<urllib3.connection.HTTPConnection object at 0x140851250>: Failed to establish a new connection: [Errno 61] Connection refused'))\n", "test_name": "test_17_mitra", "rerun": "0"}, "17": {"status": "FAIL", "message": "           ConnectionRefusedError: [Errno 61] Connection refused\n       urllib3.exceptions.NewConnectionError: <urllib3.connection.HTTPConnection object at 0x142d133d0>: Failed to establish a new connection: [Errno 61] Connection refused\n       urllib3.exceptions.MaxRetryError: HTTPConnectionPool(host='localhost', port=54091): Max retries exceeded with url: /session/6989a4b9db5e64b95268f36aa5d0a2f6/timeouts (Caused by NewConnectionError('<urllib3.connection.HTTPConnection object at 0x142d133d0>: Failed to establish a new connection: [Errno 61] Connection refused'))\n", "test_name": "test_18_InputGambar", "rerun": "0"}, "18": {"status": "FAIL", "message": "           ConnectionRefusedError: [Errno 61] Connection refused\n       urllib3.exceptions.NewConnectionError: <urllib3.connection.HTTPConnection object at 0x142d17280>: Failed to establish a new connection: [Errno 61] Connection refused\n       urllib3.exceptions.MaxRetryError: HTTPConnectionPool(host='localhost', port=54091): Max retries exceeded with url: /session/6989a4b9db5e64b95268f36aa5d0a2f6/timeouts (Caused by NewConnectionError('<urllib3.connection.HTTPConnection object at 0x142d17280>: Failed to establish a new connection: [Errno 61] Connection refused'))\n", "test_name": "test_19_Keterangan", "rerun": "0"}, "19": {"status": "FAIL", "message": "           ConnectionRefusedError: [Errno 61] Connection refused\n       urllib3.exceptions.NewConnectionError: <urllib3.connection.HTTPConnection object at 0x142cd6cd0>: Failed to establish a new connection: [Errno 61] Connection refused\n       urllib3.exceptions.MaxRetryError: HTTPConnectionPool(host='localhost', port=54091): Max retries exceeded with url: /session/6989a4b9db5e64b95268f36aa5d0a2f6/timeouts (Caused by NewConnectionError('<urllib3.connection.HTTPConnection object at 0x142cd6cd0>: Failed to establish a new connection: [Errno 61] Connection refused'))\n", "test_name": "test_20_tambahPeserta", "rerun": "0"}, "20": {"status": "FAIL", "message": "           ConnectionRefusedError: [Errno 61] Connection refused\n       urllib3.exceptions.NewConnectionError: <urllib3.connection.HTTPConnection object at 0x142e621c0>: Failed to establish a new connection: [Errno 61] Connection refused\n       urllib3.exceptions.MaxRetryError: HTTPConnectionPool(host='localhost', port=54091): Max retries exceeded with url: /session/6989a4b9db5e64b95268f36aa5d0a2f6/window (Caused by NewConnectionError('<urllib3.connection.HTTPConnection object at 0x142e621c0>: Failed to establish a new connection: [Errno 61] Connection refused'))\n", "test_name": "test_32_exit", "rerun": "0"}}, "suite_name": "1.KegiatanKerja/Fungsional/test_GiatjaTambah.py"}}}, "date": "May 03, 2023", "start_time": 1683092347.894799, "total_suite": 1, "status": "FAIL", "status_list": {"pass": "15", "fail": "6", "skip": "0", "error": "0", "xpass": "0", "xfail": "0", "rerun": "0"}, "total_tests": "21"}