{"content": {"suites": {"0": {"status": {"total_pass": 3, "total_skip": 0, "total_xpass": 0, "total_xfail": 0, "total_rerun": 0, "total_fail": 6, "total_error": 0}, "tests": {"0": {"status": "PASS", "message": "", "test_name": "test_SetupOs", "rerun": "0"}, "1": {"status": "PASS", "message": "", "test_name": "test_TC_GIATJA_001", "rerun": "0"}, "2": {"status": "PASS", "message": "", "test_name": "test_TC_GIATJA_002", "rerun": "0"}, "3": {"status": "FAIL", "message": "   selenium.common.exceptions.ElementClickInterceptedException: Message: element click intercepted: Element <button class=\"el-button el-button--primary el-button--small is-plain w-full\" type=\"button\" id=\"uploadButton\">...</button> is not clickable at point (341, 768). Other element would receive the click: <span>...</span>\n     (Session info: chrome=112.0.5615.137)\n   Stacktrace:\n   0   chromedriver                        0x0000000104b4cae8 chromedriver + 4958952\n   1   chromedriver                        0x0000000104b447b3 chromedriver + 4925363\n   2   chromedriver                        0x00000001047061d6 chromedriver + 475606\n   3   chromedriver                        0x0000000104753321 chromedriver + 791329\n   4   chromedriver                        0x000000010475036e chromedriver + 779118\n   5   chromedriver                        0x000000010474cfd4 chromedriver + 765908\n   6   chromedriver                        0x000000010474b9af chromedriver + 760239\n   7   chromedriver                        0x000000010473c283 chromedriver + 696963\n   8   chromedriver                        0x000000010476fc12 chromedriver + 908306\n   9   chromedriver                        0x000000010473b8f1 chromedriver + 694513\n   10  chromedriver                        0x000000010476fdce chromedriver + 908750\n   11  chromedriver                        0x000000010478b25b chromedriver + 1020507\n   12  chromedriver                        0x000000010476f9e3 chromedriver + 907747\n   13  chromedriver                        0x0000000104739aef chromedriver + 686831\n   14  chromedriver                        0x000000010473b00e chromedriver + 692238\n   15  chromedriver                        0x0000000104b089ad chromedriver + 4680109\n   16  chromedriver                        0x0000000104b0dc12 chromedriver + 4701202\n   17  chromedriver                        0x0000000104b1479f chromedriver + 4728735\n   18  chromedriver                        0x0000000104b0eb7a chromedriver + 4705146\n   19  chromedriver                        0x0000000104ae127e chromedriver + 4518526\n   20  chromedriver                        0x0000000104b2e908 chromedriver + 4835592\n   21  chromedriver                        0x0000000104b2ea87 chromedriver + 4835975\n   22  chromedriver                        0x0000000104b3e00f chromedriver + 4898831\n   23  libsystem_pthread.dylib             0x00007ff80f4a71d3 _pthread_start + 125\n   24  libsystem_pthread.dylib             0x00007ff80f4a2bd3 thread_start + 15\n       assert False\n", "test_name": "test_4_TC_GIATJA_003", "rerun": "0"}, "4": {"status": "FAIL", "message": "           ConnectionRefusedError: [Errno 61] Connection refused\n       urllib3.exceptions.NewConnectionError: <urllib3.connection.HTTPConnection object at 0x12c6533a0>: Failed to establish a new connection: [Errno 61] Connection refused\n       urllib3.exceptions.MaxRetryError: HTTPConnectionPool(host='localhost', port=57730): Max retries exceeded with url: /session/f11741516c1ed43d6e0b7db7a4ddd01e/timeouts (Caused by NewConnectionError('<urllib3.connection.HTTPConnection object at 0x12c6533a0>: Failed to establish a new connection: [Errno 61] Connection refused'))\n", "test_name": "test_TC_GIATJA_004", "rerun": "0"}, "5": {"status": "FAIL", "message": "           ConnectionRefusedError: [Errno 61] Connection refused\n       urllib3.exceptions.NewConnectionError: <urllib3.connection.HTTPConnection object at 0x12c9dc250>: Failed to establish a new connection: [Errno 61] Connection refused\n       urllib3.exceptions.MaxRetryError: HTTPConnectionPool(host='localhost', port=57730): Max retries exceeded with url: /session/f11741516c1ed43d6e0b7db7a4ddd01e/element (Caused by NewConnectionError('<urllib3.connection.HTTPConnection object at 0x12c9dc250>: Failed to establish a new connection: [Errno 61] Connection refused'))\n", "test_name": "test_TC_GIATJA_005", "rerun": "0"}, "6": {"status": "FAIL", "message": "           ConnectionRefusedError: [Errno 61] Connection refused\n       urllib3.exceptions.NewConnectionError: <urllib3.connection.HTTPConnection object at 0x12ca21f40>: Failed to establish a new connection: [Errno 61] Connection refused\n       urllib3.exceptions.MaxRetryError: HTTPConnectionPool(host='localhost', port=57730): Max retries exceeded with url: /session/f11741516c1ed43d6e0b7db7a4ddd01e/element (Caused by NewConnectionError('<urllib3.connection.HTTPConnection object at 0x12ca21f40>: Failed to establish a new connection: [Errno 61] Connection refused'))\n", "test_name": "test_TC_GIATJA_006", "rerun": "0"}, "7": {"status": "FAIL", "message": "           ConnectionRefusedError: [Errno 61] Connection refused\n       urllib3.exceptions.NewConnectionError: <urllib3.connection.HTTPConnection object at 0x12c660310>: Failed to establish a new connection: [Errno 61] Connection refused\n       urllib3.exceptions.MaxRetryError: HTTPConnectionPool(host='localhost', port=57730): Max retries exceeded with url: /session/f11741516c1ed43d6e0b7db7a4ddd01e/element (Caused by NewConnectionError('<urllib3.connection.HTTPConnection object at 0x12c660310>: Failed to establish a new connection: [Errno 61] Connection refused'))\n", "test_name": "test_TC_GIATJA_007", "rerun": "0"}, "8": {"status": "FAIL", "message": "           ConnectionRefusedError: [Errno 61] Connection refused\n       urllib3.exceptions.NewConnectionError: <urllib3.connection.HTTPConnection object at 0x12ca04850>: Failed to establish a new connection: [Errno 61] Connection refused\n       urllib3.exceptions.MaxRetryError: HTTPConnectionPool(host='localhost', port=57730): Max retries exceeded with url: /session/f11741516c1ed43d6e0b7db7a4ddd01e/window (Caused by NewConnectionError('<urllib3.connection.HTTPConnection object at 0x12ca04850>: Failed to establish a new connection: [Errno 61] Connection refused'))\n", "test_name": "test_exit", "rerun": "0"}}, "suite_name": "1.KegiatanKerja/Fungsional/test_OpGiatja.py"}}}, "date": "May 03, 2023", "start_time": 1683104560.5211542, "total_suite": 1, "status": "FAIL", "status_list": {"pass": "3", "fail": "6", "skip": "0", "error": "0", "xpass": "0", "xfail": "0", "rerun": "0"}, "total_tests": "9"}