{"content": {"suites": {"0": {"status": {"total_pass": 3, "total_skip": 0, "total_xpass": 0, "total_xfail": 0, "total_rerun": 0, "total_fail": 6, "total_error": 0}, "tests": {"0": {"status": "PASS", "message": "", "test_name": "test_SetupOsOpen", "rerun": "0"}, "1": {"status": "PASS", "message": "", "test_name": "test_TC_GIATJA_001", "rerun": "0"}, "2": {"status": "PASS", "message": "", "test_name": "test_TC_GIATJA_002", "rerun": "0"}, "3": {"status": "FAIL", "message": "   selenium.common.exceptions.ElementClickInterceptedException: Message: element click intercepted: Element <li class=\"el-select-dropdown__item\" id=\"skala2\">...</li> is not clickable at point (838, 508). Other element would receive the click: <li class=\"el-select-dropdown__item\" id=\"skala1\">...</li>\n     (Session info: chrome=113.0.5672.63)\n   Stacktrace:\n   0   chromedriver                        0x00000001051bcae8 chromedriver + 4958952\n   1   chromedriver                        0x00000001051b47b3 chromedriver + 4925363\n   2   chromedriver                        0x0000000104d761d6 chromedriver + 475606\n   3   chromedriver                        0x0000000104dc3321 chromedriver + 791329\n   4   chromedriver                        0x0000000104dc036e chromedriver + 779118\n   5   chromedriver                        0x0000000104dbcfd4 chromedriver + 765908\n   6   chromedriver                        0x0000000104dbb9af chromedriver + 760239\n   7   chromedriver                        0x0000000104dac283 chromedriver + 696963\n   8   chromedriver                        0x0000000104ddfc12 chromedriver + 908306\n   9   chromedriver                        0x0000000104dab8f1 chromedriver + 694513\n   10  chromedriver                        0x0000000104ddfdce chromedriver + 908750\n   11  chromedriver                        0x0000000104dfb25b chromedriver + 1020507\n   12  chromedriver                        0x0000000104ddf9e3 chromedriver + 907747\n   13  chromedriver                        0x0000000104da9aef chromedriver + 686831\n   14  chromedriver                        0x0000000104dab00e chromedriver + 692238\n   15  chromedriver                        0x00000001051789ad chromedriver + 4680109\n   16  chromedriver                        0x000000010517dc12 chromedriver + 4701202\n   17  chromedriver                        0x000000010518479f chromedriver + 4728735\n   18  chromedriver                        0x000000010517eb7a chromedriver + 4705146\n   19  chromedriver                        0x000000010515127e chromedriver + 4518526\n   20  chromedriver                        0x000000010519e908 chromedriver + 4835592\n   21  chromedriver                        0x000000010519ea87 chromedriver + 4835975\n   22  chromedriver                        0x00000001051ae00f chromedriver + 4898831\n   23  libsystem_pthread.dylib             0x00007ff808d0f1d3 _pthread_start + 125\n   24  libsystem_pthread.dylib             0x00007ff808d0abd3 thread_start + 15\n       assert False\n", "test_name": "test_TC_GIATJA_003", "rerun": "0"}, "4": {"status": "FAIL", "message": "           ConnectionRefusedError: [Errno 61] Connection refused\n       urllib3.exceptions.NewConnectionError: <urllib3.connection.HTTPConnection object at 0x1249b1070>: Failed to establish a new connection: [Errno 61] Connection refused\n       urllib3.exceptions.MaxRetryError: HTTPConnectionPool(host='localhost', port=53033): Max retries exceeded with url: /session/5ecd5f3122af08ee6290de71e59880a9/timeouts (Caused by NewConnectionError('<urllib3.connection.HTTPConnection object at 0x1249b1070>: Failed to establish a new connection: [Errno 61] Connection refused'))\n", "test_name": "test_TC_GIATJA_004", "rerun": "0"}, "5": {"status": "FAIL", "message": "           ConnectionRefusedError: [Errno 61] Connection refused\n       urllib3.exceptions.NewConnectionError: <urllib3.connection.HTTPConnection object at 0x124cd5340>: Failed to establish a new connection: [Errno 61] Connection refused\n       urllib3.exceptions.MaxRetryError: HTTPConnectionPool(host='localhost', port=53033): Max retries exceeded with url: /session/5ecd5f3122af08ee6290de71e59880a9/timeouts (Caused by NewConnectionError('<urllib3.connection.HTTPConnection object at 0x124cd5340>: Failed to establish a new connection: [Errno 61] Connection refused'))\n", "test_name": "test_TC_GIATJA_005", "rerun": "0"}, "6": {"status": "FAIL", "message": "           ConnectionRefusedError: [Errno 61] Connection refused\n       urllib3.exceptions.NewConnectionError: <urllib3.connection.HTTPConnection object at 0x1249f50d0>: Failed to establish a new connection: [Errno 61] Connection refused\n       urllib3.exceptions.MaxRetryError: HTTPConnectionPool(host='localhost', port=53033): Max retries exceeded with url: /session/5ecd5f3122af08ee6290de71e59880a9/timeouts (Caused by NewConnectionError('<urllib3.connection.HTTPConnection object at 0x1249f50d0>: Failed to establish a new connection: [Errno 61] Connection refused'))\n", "test_name": "test_TC_GIATJA_006", "rerun": "0"}, "7": {"status": "FAIL", "message": "           ConnectionRefusedError: [Errno 61] Connection refused\n       urllib3.exceptions.NewConnectionError: <urllib3.connection.HTTPConnection object at 0x124d13100>: Failed to establish a new connection: [Errno 61] Connection refused\n       urllib3.exceptions.MaxRetryError: HTTPConnectionPool(host='localhost', port=53033): Max retries exceeded with url: /session/5ecd5f3122af08ee6290de71e59880a9/element (Caused by NewConnectionError('<urllib3.connection.HTTPConnection object at 0x124d13100>: Failed to establish a new connection: [Errno 61] Connection refused'))\n", "test_name": "test_TC_GIATJA_007", "rerun": "0"}, "8": {"status": "FAIL", "message": "           ConnectionRefusedError: [Errno 61] Connection refused\n       urllib3.exceptions.NewConnectionError: <urllib3.connection.HTTPConnection object at 0x1249e0c10>: Failed to establish a new connection: [Errno 61] Connection refused\n       urllib3.exceptions.MaxRetryError: HTTPConnectionPool(host='localhost', port=53033): Max retries exceeded with url: /session/5ecd5f3122af08ee6290de71e59880a9/window (Caused by NewConnectionError('<urllib3.connection.HTTPConnection object at 0x1249e0c10>: Failed to establish a new connection: [Errno 61] Connection refused'))\n", "test_name": "test_EXIT", "rerun": "0"}}, "suite_name": "1.KegiatanKerja/Fungsional/test_OpGiatja.py"}}}, "date": "May 04, 2023", "start_time": 1683174862.239153, "total_suite": 1, "status": "FAIL", "status_list": {"pass": "3", "fail": "6", "skip": "0", "error": "0", "xpass": "0", "xfail": "0", "rerun": "0"}, "total_tests": "9"}