{"content": {"suites": {"0": {"status": {"total_pass": 3, "total_skip": 0, "total_xpass": 0, "total_xfail": 0, "total_rerun": 0, "total_fail": 8, "total_error": 0}, "tests": {"0": {"status": "PASS", "message": "", "test_name": "test_1_SetupOs", "rerun": "0"}, "1": {"status": "PASS", "message": "", "test_name": "test_2_Login", "rerun": "0"}, "2": {"status": "PASS", "message": "", "test_name": "test_2_AksesMenu", "rerun": "0"}, "3": {"status": "FAIL", "message": "   selenium.common.exceptions.TimeoutException: Message: \n   Stacktrace:\n   0   chromedriver                        0x0000000103472ae8 chromedriver + 4958952\n   1   chromedriver                        0x000000010346a7b3 chromedriver + 4925363\n   2   chromedriver                        0x000000010302c1d6 chromedriver + 475606\n   3   chromedriver                        0x000000010306fa20 chromedriver + 752160\n   4   chromedriver                        0x000000010306fc81 chromedriver + 752769\n   5   chromedriver                        0x00000001030b3f64 chromedriver + 1032036\n   6   chromedriver                        0x0000000103095c3d chromedriver + 908349\n   7   chromedriver                        0x00000001030b125b chromedriver + 1020507\n   8   chromedriver                        0x00000001030959e3 chromedriver + 907747\n   9   chromedriver                        0x000000010305faef chromedriver + 686831\n   10  chromedriver                        0x000000010306100e chromedriver + 692238\n   11  chromedriver                        0x000000010342e9ad chromedriver + 4680109\n   12  chromedriver                        0x0000000103433c12 chromedriver + 4701202\n   13  chromedriver                        0x000000010343a79f chromedriver + 4728735\n   14  chromedriver                        0x0000000103434b7a chromedriver + 4705146\n   15  chromedriver                        0x000000010340727e chromedriver + 4518526\n   16  chromedriver                        0x0000000103454908 chromedriver + 4835592\n   17  chromedriver                        0x0000000103454a87 chromedriver + 4835975\n   18  chromedriver                        0x000000010346400f chromedriver + 4898831\n   19  libsystem_pthread.dylib             0x00007ff815ce31d3 _pthread_start + 125\n   20  libsystem_pthread.dylib             0x00007ff815cdebd3 thread_start + 15\n       assert False\n", "test_name": "test_3_CreateButton", "rerun": "0"}, "4": {"status": "FAIL", "message": "           ConnectionRefusedError: [Errno 61] Connection refused\n       urllib3.exceptions.NewConnectionError: <urllib3.connection.HTTPConnection object at 0x12a0653a0>: Failed to establish a new connection: [Errno 61] Connection refused\n       urllib3.exceptions.MaxRetryError: HTTPConnectionPool(host='localhost', port=49718): Max retries exceeded with url: /session/6d7b267724ce8ab320c8ac1d12f25ab0/timeouts (Caused by NewConnectionError('<urllib3.connection.HTTPConnection object at 0x12a0653a0>: Failed to establish a new connection: [Errno 61] Connection refused'))\n", "test_name": "test_4_InputLokasiKegiatan", "rerun": "0"}, "5": {"status": "FAIL", "message": "           ConnectionRefusedError: [Errno 61] Connection refused\n       urllib3.exceptions.NewConnectionError: <urllib3.connection.HTTPConnection object at 0x12c4342e0>: Failed to establish a new connection: [Errno 61] Connection refused\n       urllib3.exceptions.MaxRetryError: HTTPConnectionPool(host='localhost', port=49718): Max retries exceeded with url: /session/6d7b267724ce8ab320c8ac1d12f25ab0/timeouts (Caused by NewConnectionError('<urllib3.connection.HTTPConnection object at 0x12c4342e0>: Failed to establish a new connection: [Errno 61] Connection refused'))\n", "test_name": "test_5_InputJumlahAgen", "rerun": "0"}, "6": {"status": "FAIL", "message": "           ConnectionRefusedError: [Errno 61] Connection refused\n       urllib3.exceptions.NewConnectionError: <urllib3.connection.HTTPConnection object at 0x12c3cafd0>: Failed to establish a new connection: [Errno 61] Connection refused\n       urllib3.exceptions.MaxRetryError: HTTPConnectionPool(host='localhost', port=49718): Max retries exceeded with url: /session/6d7b267724ce8ab320c8ac1d12f25ab0/timeouts (Caused by NewConnectionError('<urllib3.connection.HTTPConnection object at 0x12c3cafd0>: Failed to establish a new connection: [Errno 61] Connection refused'))\n           ConnectionRefusedError: [Errno 61] Connection refused\n       urllib3.exceptions.NewConnectionError: <urllib3.connection.HTTPConnection object at 0x12c3c5400>: Failed to establish a new connection: [Errno 61] Connection refused\n       urllib3.exceptions.MaxRetryError: HTTPConnectionPool(host='localhost', port=49718): Max retries exceeded with url: /session/6d7b267724ce8ab320c8ac1d12f25ab0/screenshot (Caused by NewConnectionError('<urllib3.connection.HTTPConnection object at 0x12c3c5400>: Failed to establish a new connection: [Errno 61] Connection refused'))\n", "test_name": "test_6_InputHasilkegiatan", "rerun": "0"}, "7": {"status": "FAIL", "message": "           ConnectionRefusedError: [Errno 61] Connection refused\n       urllib3.exceptions.NewConnectionError: <urllib3.connection.HTTPConnection object at 0x12c470460>: Failed to establish a new connection: [Errno 61] Connection refused\n       urllib3.exceptions.MaxRetryError: HTTPConnectionPool(host='localhost', port=49718): Max retries exceeded with url: /session/6d7b267724ce8ab320c8ac1d12f25ab0/timeouts (Caused by NewConnectionError('<urllib3.connection.HTTPConnection object at 0x12c470460>: Failed to establish a new connection: [Errno 61] Connection refused'))\n", "test_name": "test_7_InputTindaklanjut", "rerun": "0"}, "8": {"status": "FAIL", "message": "           ConnectionRefusedError: [Errno 61] Connection refused\n       urllib3.exceptions.NewConnectionError: <urllib3.connection.HTTPConnection object at 0x12c2f5190>: Failed to establish a new connection: [Errno 61] Connection refused\n       urllib3.exceptions.MaxRetryError: HTTPConnectionPool(host='localhost', port=49718): Max retries exceeded with url: /session/6d7b267724ce8ab320c8ac1d12f25ab0/timeouts (Caused by NewConnectionError('<urllib3.connection.HTTPConnection object at 0x12c2f5190>: Failed to establish a new connection: [Errno 61] Connection refused'))\n", "test_name": "test_8_InputKeterangan", "rerun": "0"}, "9": {"status": "FAIL", "message": "           ConnectionRefusedError: [Errno 61] Connection refused\n       urllib3.exceptions.NewConnectionError: <urllib3.connection.HTTPConnection object at 0x12c225370>: Failed to establish a new connection: [Errno 61] Connection refused\n       urllib3.exceptions.MaxRetryError: HTTPConnectionPool(host='localhost', port=49718): Max retries exceeded with url: /session/6d7b267724ce8ab320c8ac1d12f25ab0/timeouts (Caused by NewConnectionError('<urllib3.connection.HTTPConnection object at 0x12c225370>: Failed to establish a new connection: [Errno 61] Connection refused'))\n", "test_name": "test_9_ClickbuttonSubmit", "rerun": "0"}, "10": {"status": "FAIL", "message": "           ConnectionRefusedError: [Errno 61] Connection refused\n       urllib3.exceptions.NewConnectionError: <urllib3.connection.HTTPConnection object at 0x12c629c10>: Failed to establish a new connection: [Errno 61] Connection refused\n       urllib3.exceptions.MaxRetryError: HTTPConnectionPool(host='localhost', port=49718): Max retries exceeded with url: /session/6d7b267724ce8ab320c8ac1d12f25ab0/window (Caused by NewConnectionError('<urllib3.connection.HTTPConnection object at 0x12c629c10>: Failed to establish a new connection: [Errno 61] Connection refused'))\n", "test_name": "test_33_exit", "rerun": "0"}}, "suite_name": "4LaporanBulanan/8.Laporan7B/Fungsional/test_Laporan7B.py"}}}, "date": "April 12, 2023", "start_time": 1681288759.656019, "total_suite": 1, "status": "FAIL", "status_list": {"pass": "3", "fail": "8", "skip": "0", "error": "0", "xpass": "0", "xfail": "0", "rerun": "0"}, "total_tests": "11"}