{"content": {"suites": {"0": {"status": {"total_pass": 3, "total_skip": 0, "total_xpass": 0, "total_xfail": 0, "total_rerun": 0, "total_fail": 6, "total_error": 0}, "tests": {"0": {"status": "PASS", "message": "", "test_name": "test_SetupOsOpen", "rerun": "0"}, "1": {"status": "PASS", "message": "", "test_name": "test_TC_GIATJA_001", "rerun": "0"}, "2": {"status": "PASS", "message": "", "test_name": "test_TC_GIATJA_002", "rerun": "0"}, "3": {"status": "FAIL", "message": "   selenium.common.exceptions.ElementClickInterceptedException: Message: element click intercepted: Element <li class=\"el-select-dropdown__item\" id=\"mitra4\">...</li> is not clickable at point (958, 680). Other element would receive the click: <input class=\"el-input__inner\" id=\"prasarana\" type=\"text\" readonly=\"\" autocomplete=\"off\" tabindex=\"-1\" placeholder=\"\" style=\"height: 32px;\">\n     (Session info: chrome=112.0.5615.137)\n   Stacktrace:\n   0   chromedriver                        0x0000000102ed1ae8 chromedriver + 4958952\n   1   chromedriver                        0x0000000102ec97b3 chromedriver + 4925363\n   2   chromedriver                        0x0000000102a8b1d6 chromedriver + 475606\n   3   chromedriver                        0x0000000102ad8321 chromedriver + 791329\n   4   chromedriver                        0x0000000102ad536e chromedriver + 779118\n   5   chromedriver                        0x0000000102ad1fd4 chromedriver + 765908\n   6   chromedriver                        0x0000000102ad09af chromedriver + 760239\n   7   chromedriver                        0x0000000102ac1283 chromedriver + 696963\n   8   chromedriver                        0x0000000102af4c12 chromedriver + 908306\n   9   chromedriver                        0x0000000102ac08f1 chromedriver + 694513\n   10  chromedriver                        0x0000000102af4dce chromedriver + 908750\n   11  chromedriver                        0x0000000102b1025b chromedriver + 1020507\n   12  chromedriver                        0x0000000102af49e3 chromedriver + 907747\n   13  chromedriver                        0x0000000102abeaef chromedriver + 686831\n   14  chromedriver                        0x0000000102ac000e chromedriver + 692238\n   15  chromedriver                        0x0000000102e8d9ad chromedriver + 4680109\n   16  chromedriver                        0x0000000102e92c12 chromedriver + 4701202\n   17  chromedriver                        0x0000000102e9979f chromedriver + 4728735\n   18  chromedriver                        0x0000000102e93b7a chromedriver + 4705146\n   19  chromedriver                        0x0000000102e6627e chromedriver + 4518526\n   20  chromedriver                        0x0000000102eb3908 chromedriver + 4835592\n   21  chromedriver                        0x0000000102eb3a87 chromedriver + 4835975\n   22  chromedriver                        0x0000000102ec300f chromedriver + 4898831\n   23  libsystem_pthread.dylib             0x00007ff80f4a71d3 _pthread_start + 125\n   24  libsystem_pthread.dylib             0x00007ff80f4a2bd3 thread_start + 15\n       assert False\n", "test_name": "test_TC_GIATJA_003", "rerun": "0"}, "4": {"status": "FAIL", "message": "           ConnectionRefusedError: [Errno 61] Connection refused\n       urllib3.exceptions.NewConnectionError: <urllib3.connection.HTTPConnection object at 0x1244315b0>: Failed to establish a new connection: [Errno 61] Connection refused\n       urllib3.exceptions.MaxRetryError: HTTPConnectionPool(host='localhost', port=51131): Max retries exceeded with url: /session/7d5047db9a9b2e5de1a0fd52d0158a4d/timeouts (Caused by NewConnectionError('<urllib3.connection.HTTPConnection object at 0x1244315b0>: Failed to establish a new connection: [Errno 61] Connection refused'))\n", "test_name": "test_TC_GIATJA_004", "rerun": "0"}, "5": {"status": "FAIL", "message": "           ConnectionRefusedError: [Errno 61] Connection refused\n       urllib3.exceptions.NewConnectionError: <urllib3.connection.HTTPConnection object at 0x125c7b280>: Failed to establish a new connection: [Errno 61] Connection refused\n       urllib3.exceptions.MaxRetryError: HTTPConnectionPool(host='localhost', port=51131): Max retries exceeded with url: /session/7d5047db9a9b2e5de1a0fd52d0158a4d/timeouts (Caused by NewConnectionError('<urllib3.connection.HTTPConnection object at 0x125c7b280>: Failed to establish a new connection: [Errno 61] Connection refused'))\n", "test_name": "test_TC_GIATJA_005", "rerun": "0"}, "6": {"status": "FAIL", "message": "           ConnectionRefusedError: [Errno 61] Connection refused\n       urllib3.exceptions.NewConnectionError: <urllib3.connection.HTTPConnection object at 0x125e3b040>: Failed to establish a new connection: [Errno 61] Connection refused\n       urllib3.exceptions.MaxRetryError: HTTPConnectionPool(host='localhost', port=51131): Max retries exceeded with url: /session/7d5047db9a9b2e5de1a0fd52d0158a4d/timeouts (Caused by NewConnectionError('<urllib3.connection.HTTPConnection object at 0x125e3b040>: Failed to establish a new connection: [Errno 61] Connection refused'))\n", "test_name": "test_TC_GIATJA_006", "rerun": "0"}, "7": {"status": "FAIL", "message": "           ConnectionRefusedError: [Errno 61] Connection refused\n       urllib3.exceptions.NewConnectionError: <urllib3.connection.HTTPConnection object at 0x125ce10a0>: Failed to establish a new connection: [Errno 61] Connection refused\n       urllib3.exceptions.MaxRetryError: HTTPConnectionPool(host='localhost', port=51131): Max retries exceeded with url: /session/7d5047db9a9b2e5de1a0fd52d0158a4d/element (Caused by NewConnectionError('<urllib3.connection.HTTPConnection object at 0x125ce10a0>: Failed to establish a new connection: [Errno 61] Connection refused'))\n", "test_name": "test_TC_GIATJA_007", "rerun": "0"}, "8": {"status": "FAIL", "message": "           ConnectionRefusedError: [Errno 61] Connection refused\n       urllib3.exceptions.NewConnectionError: <urllib3.connection.HTTPConnection object at 0x125cac250>: Failed to establish a new connection: [Errno 61] Connection refused\n       urllib3.exceptions.MaxRetryError: HTTPConnectionPool(host='localhost', port=51131): Max retries exceeded with url: /session/7d5047db9a9b2e5de1a0fd52d0158a4d/window (Caused by NewConnectionError('<urllib3.connection.HTTPConnection object at 0x125cac250>: Failed to establish a new connection: [Errno 61] Connection refused'))\n", "test_name": "test_EXIT", "rerun": "0"}}, "suite_name": "1.KegiatanKerja/Fungsional/test_OpGiatja.py"}}}, "date": "May 03, 2023", "start_time": 1683108173.4425101, "total_suite": 1, "status": "FAIL", "status_list": {"pass": "3", "fail": "6", "skip": "0", "error": "0", "xpass": "0", "xfail": "0", "rerun": "0"}, "total_tests": "9"}