{"content": {"suites": {"0": {"status": {"total_pass": 1, "total_skip": 0, "total_xpass": 0, "total_xfail": 0, "total_rerun": 0, "total_fail": 4, "total_error": 0}, "tests": {"0": {"status": "PASS", "message": "", "test_name": "test_1_SetupOS", "rerun": "0"}, "1": {"status": "FAIL", "message": "       http.client.RemoteDisconnected: Remote end closed connection without response\n       urllib3.exceptions.ProtocolError: ('Connection aborted.', RemoteDisconnected('Remote end closed connection without response'))\n", "test_name": "test_2_Login", "rerun": "0"}, "2": {"status": "FAIL", "message": "           ConnectionRefusedError: [Errno 61] Connection refused\n       urllib3.exceptions.NewConnectionError: <urllib3.connection.HTTPConnection object at 0x117106700>: Failed to establish a new connection: [Errno 61] Connection refused\n       urllib3.exceptions.MaxRetryError: HTTPConnectionPool(host='localhost', port=59601): Max retries exceeded with url: /session/ed9d36997b06fb0c72d14be6bee25dd3/timeouts (Caused by NewConnectionError('<urllib3.connection.HTTPConnection object at 0x117106700>: Failed to establish a new connection: [Errno 61] Connection refused'))\n", "test_name": "test_3_Akses_menu", "rerun": "0"}, "3": {"status": "FAIL", "message": "           ConnectionRefusedError: [Errno 61] Connection refused\n       urllib3.exceptions.NewConnectionError: <urllib3.connection.HTTPConnection object at 0x1157d6520>: Failed to establish a new connection: [Errno 61] Connection refused\n       urllib3.exceptions.MaxRetryError: HTTPConnectionPool(host='localhost', port=59601): Max retries exceeded with url: /session/ed9d36997b06fb0c72d14be6bee25dd3/timeouts (Caused by NewConnectionError('<urllib3.connection.HTTPConnection object at 0x1157d6520>: Failed to establish a new connection: [Errno 61] Connection refused'))\n", "test_name": "test_4_ButtonTambah_PegawaiTambah", "rerun": "0"}, "4": {"status": "FAIL", "message": "           ConnectionRefusedError: [Errno 61] Connection refused\n       urllib3.exceptions.NewConnectionError: <urllib3.connection.HTTPConnection object at 0x117361f70>: Failed to establish a new connection: [Errno 61] Connection refused\n       urllib3.exceptions.MaxRetryError: HTTPConnectionPool(host='localhost', port=59601): Max retries exceeded with url: /session/ed9d36997b06fb0c72d14be6bee25dd3/timeouts (Caused by NewConnectionError('<urllib3.connection.HTTPConnection object at 0x117361f70>: Failed to establish a new connection: [Errno 61] Connection refused'))\n", "test_name": "test_5_Input", "rerun": "0"}}, "suite_name": "test_2Fungsi_P2U_ManualTambah.py"}}}, "date": "December 02, 2022", "start_time": 1669995761.5993652, "total_suite": 1, "status": "FAIL", "status_list": {"pass": "1", "fail": "4", "skip": "0", "error": "0", "xpass": "0", "xfail": "0", "rerun": "0"}, "total_tests": "5"}