{"content": {"suites": {"0": {"status": {"total_pass": 3, "total_skip": 0, "total_xpass": 0, "total_xfail": 0, "total_rerun": 0, "total_fail": 9, "total_error": 0}, "tests": {"0": {"status": "PASS", "message": "", "test_name": "test_1_SetupOs", "rerun": "0"}, "1": {"status": "PASS", "message": "", "test_name": "test_2_Login", "rerun": "0"}, "2": {"status": "PASS", "message": "", "test_name": "test_2_AksesMenu", "rerun": "0"}, "3": {"status": "FAIL", "message": "   selenium.common.exceptions.TimeoutException: Message: \n   Stacktrace:\n   0   chromedriver                        0x0000000104961ae8 chromedriver + 4958952\n   1   chromedriver                        0x00000001049597b3 chromedriver + 4925363\n   2   chromedriver                        0x000000010451b1d6 chromedriver + 475606\n   3   chromedriver                        0x000000010455ea20 chromedriver + 752160\n   4   chromedriver                        0x000000010455ec81 chromedriver + 752769\n   5   chromedriver                        0x00000001045a2f64 chromedriver + 1032036\n   6   chromedriver                        0x0000000104584c3d chromedriver + 908349\n   7   chromedriver                        0x00000001045a025b chromedriver + 1020507\n   8   chromedriver                        0x00000001045849e3 chromedriver + 907747\n   9   chromedriver                        0x000000010454eaef chromedriver + 686831\n   10  chromedriver                        0x000000010455000e chromedriver + 692238\n   11  chromedriver                        0x000000010491d9ad chromedriver + 4680109\n   12  chromedriver                        0x0000000104922c12 chromedriver + 4701202\n   13  chromedriver                        0x000000010492979f chromedriver + 4728735\n   14  chromedriver                        0x0000000104923b7a chromedriver + 4705146\n   15  chromedriver                        0x00000001048f627e chromedriver + 4518526\n   16  chromedriver                        0x0000000104943908 chromedriver + 4835592\n   17  chromedriver                        0x0000000104943a87 chromedriver + 4835975\n   18  chromedriver                        0x000000010495300f chromedriver + 4898831\n   19  libsystem_pthread.dylib             0x00007ff815ce31d3 _pthread_start + 125\n   20  libsystem_pthread.dylib             0x00007ff815cdebd3 thread_start + 15\n       assert False\n", "test_name": "test_3_CreateButton", "rerun": "0"}, "4": {"status": "FAIL", "message": "           ConnectionRefusedError: [Errno 61] Connection refused\n       urllib3.exceptions.NewConnectionError: <urllib3.connection.HTTPConnection object at 0x117b632e0>: Failed to establish a new connection: [Errno 61] Connection refused\n       urllib3.exceptions.MaxRetryError: HTTPConnectionPool(host='localhost', port=58864): Max retries exceeded with url: /session/78e45a4ccebda5b290d7811d84bee49f/timeouts (Caused by NewConnectionError('<urllib3.connection.HTTPConnection object at 0x117b632e0>: Failed to establish a new connection: [Errno 61] Connection refused'))\n", "test_name": "test_4_InpuNoSuratPerintah", "rerun": "0"}, "5": {"status": "FAIL", "message": "           ConnectionRefusedError: [Errno 61] Connection refused\n       urllib3.exceptions.NewConnectionError: <urllib3.connection.HTTPConnection object at 0x117f8b250>: Failed to establish a new connection: [Errno 61] Connection refused\n       urllib3.exceptions.MaxRetryError: HTTPConnectionPool(host='localhost', port=58864): Max retries exceeded with url: /session/78e45a4ccebda5b290d7811d84bee49f/timeouts (Caused by NewConnectionError('<urllib3.connection.HTTPConnection object at 0x117f8b250>: Failed to establish a new connection: [Errno 61] Connection refused'))\n", "test_name": "test_5_InputTanggalPelaksanaan", "rerun": "0"}, "6": {"status": "FAIL", "message": "           ConnectionRefusedError: [Errno 61] Connection refused\n       urllib3.exceptions.NewConnectionError: <urllib3.connection.HTTPConnection object at 0x117d1f280>: Failed to establish a new connection: [Errno 61] Connection refused\n       urllib3.exceptions.MaxRetryError: HTTPConnectionPool(host='localhost', port=58864): Max retries exceeded with url: /session/78e45a4ccebda5b290d7811d84bee49f/timeouts (Caused by NewConnectionError('<urllib3.connection.HTTPConnection object at 0x117d1f280>: Failed to establish a new connection: [Errno 61] Connection refused'))\n", "test_name": "test_6_InputBlok", "rerun": "0"}, "7": {"status": "FAIL", "message": "           ConnectionRefusedError: [Errno 61] Connection refused\n       urllib3.exceptions.NewConnectionError: <urllib3.connection.HTTPConnection object at 0x117d32220>: Failed to establish a new connection: [Errno 61] Connection refused\n       urllib3.exceptions.MaxRetryError: HTTPConnectionPool(host='localhost', port=58864): Max retries exceeded with url: /session/78e45a4ccebda5b290d7811d84bee49f/timeouts (Caused by NewConnectionError('<urllib3.connection.HTTPConnection object at 0x117d32220>: Failed to establish a new connection: [Errno 61] Connection refused'))\n", "test_name": "test_7_lantai", "rerun": "0"}, "8": {"status": "FAIL", "message": "           ConnectionRefusedError: [Errno 61] Connection refused\n       urllib3.exceptions.NewConnectionError: <urllib3.connection.HTTPConnection object at 0x117d494c0>: Failed to establish a new connection: [Errno 61] Connection refused\n       urllib3.exceptions.MaxRetryError: HTTPConnectionPool(host='localhost', port=58864): Max retries exceeded with url: /session/78e45a4ccebda5b290d7811d84bee49f/timeouts (Caused by NewConnectionError('<urllib3.connection.HTTPConnection object at 0x117d494c0>: Failed to establish a new connection: [Errno 61] Connection refused'))\n", "test_name": "test_8_InputKamar", "rerun": "0"}, "9": {"status": "FAIL", "message": "           ConnectionRefusedError: [Errno 61] Connection refused\n       urllib3.exceptions.NewConnectionError: <urllib3.connection.HTTPConnection object at 0x117e9f400>: Failed to establish a new connection: [Errno 61] Connection refused\n       urllib3.exceptions.MaxRetryError: HTTPConnectionPool(host='localhost', port=58864): Max retries exceeded with url: /session/78e45a4ccebda5b290d7811d84bee49f/timeouts (Caused by NewConnectionError('<urllib3.connection.HTTPConnection object at 0x117e9f400>: Failed to establish a new connection: [Errno 61] Connection refused'))\n", "test_name": "test_9_InputKeterangan", "rerun": "0"}, "10": {"status": "FAIL", "message": "           ConnectionRefusedError: [Errno 61] Connection refused\n       urllib3.exceptions.NewConnectionError: <urllib3.connection.HTTPConnection object at 0x117ba7bb0>: Failed to establish a new connection: [Errno 61] Connection refused\n       urllib3.exceptions.MaxRetryError: HTTPConnectionPool(host='localhost', port=58864): Max retries exceeded with url: /session/78e45a4ccebda5b290d7811d84bee49f/timeouts (Caused by NewConnectionError('<urllib3.connection.HTTPConnection object at 0x117ba7bb0>: Failed to establish a new connection: [Errno 61] Connection refused'))\n", "test_name": "test_10_InputNamaBarang", "rerun": "0"}, "11": {"status": "FAIL", "message": "           ConnectionRefusedError: [Errno 61] Connection refused\n       urllib3.exceptions.NewConnectionError: <urllib3.connection.HTTPConnection object at 0x1310bb1c0>: Failed to establish a new connection: [Errno 61] Connection refused\n       urllib3.exceptions.MaxRetryError: HTTPConnectionPool(host='localhost', port=58864): Max retries exceeded with url: /session/78e45a4ccebda5b290d7811d84bee49f/timeouts (Caused by NewConnectionError('<urllib3.connection.HTTPConnection object at 0x1310bb1c0>: Failed to establish a new connection: [Errno 61] Connection refused'))\n", "test_name": "test_11_InputJumlah", "rerun": "0"}}, "suite_name": "4LaporanBulanan/7.Laporan7A/Fungsional/test_Laporan7A.py"}}}, "date": "April 12, 2023", "start_time": 1681284972.066968, "total_suite": 1, "status": "FAIL", "status_list": {"pass": "3", "fail": "9", "skip": "0", "error": "0", "xpass": "0", "xfail": "0", "rerun": "0"}, "total_tests": "12"}