{"content": {"suites": {"0": {"status": {"total_pass": 6, "total_skip": 0, "total_xpass": 0, "total_xfail": 0, "total_rerun": 0, "total_fail": 5, "total_error": 0}, "tests": {"0": {"status": "PASS", "message": "", "test_name": "test_1_SetupOs", "rerun": "0"}, "1": {"status": "PASS", "message": "", "test_name": "test_2_Login", "rerun": "0"}, "2": {"status": "PASS", "message": "", "test_name": "test_3_AksesMenu", "rerun": "0"}, "3": {"status": "PASS", "message": "", "test_name": "test_4_ClickButtonEdit", "rerun": "0"}, "4": {"status": "FAIL", "message": "           ConnectionRefusedError: [Errno 61] Connection refused\n       urllib3.exceptions.NewConnectionError: <urllib3.connection.HTTPConnection object at 0x1247498b0>: Failed to establish a new connection: [Errno 61] Connection refused\n       urllib3.exceptions.MaxRetryError: HTTPConnectionPool(host='localhost', port=59788): Max retries exceeded with url: /session/2a406696e0202d8c2092d8a018d93ad9/timeouts (Caused by NewConnectionError('<urllib3.connection.HTTPConnection object at 0x1247498b0>: Failed to establish a new connection: [Errno 61] Connection refused'))\n", "test_name": "test_5_PetugasPenangkap", "rerun": "0"}, "5": {"status": "FAIL", "message": "           ConnectionRefusedError: [Errno 61] Connection refused\n       urllib3.exceptions.NewConnectionError: <urllib3.connection.HTTPConnection object at 0x124bc8370>: Failed to establish a new connection: [Errno 61] Connection refused\n       urllib3.exceptions.MaxRetryError: HTTPConnectionPool(host='localhost', port=59788): Max retries exceeded with url: /session/2a406696e0202d8c2092d8a018d93ad9/timeouts (Caused by NewConnectionError('<urllib3.connection.HTTPConnection object at 0x124bc8370>: Failed to establish a new connection: [Errno 61] Connection refused'))\n", "test_name": "test_6_LariDari", "rerun": "0"}, "6": {"status": "FAIL", "message": "           ConnectionRefusedError: [Errno 61] Connection refused\n       urllib3.exceptions.NewConnectionError: <urllib3.connection.HTTPConnection object at 0x1248d93a0>: Failed to establish a new connection: [Errno 61] Connection refused\n       urllib3.exceptions.MaxRetryError: HTTPConnectionPool(host='localhost', port=59788): Max retries exceeded with url: /session/2a406696e0202d8c2092d8a018d93ad9/timeouts (Caused by NewConnectionError('<urllib3.connection.HTTPConnection object at 0x1248d93a0>: Failed to establish a new connection: [Errno 61] Connection refused'))\n", "test_name": "test_7_KondisiFisik", "rerun": "0"}, "7": {"status": "FAIL", "message": "           ConnectionRefusedError: [Errno 61] Connection refused\n       urllib3.exceptions.NewConnectionError: <urllib3.connection.HTTPConnection object at 0x124bbb250>: Failed to establish a new connection: [Errno 61] Connection refused\n       urllib3.exceptions.MaxRetryError: HTTPConnectionPool(host='localhost', port=59788): Max retries exceeded with url: /session/2a406696e0202d8c2092d8a018d93ad9/timeouts (Caused by NewConnectionError('<urllib3.connection.HTTPConnection object at 0x124bbb250>: Failed to establish a new connection: [Errno 61] Connection refused'))\n", "test_name": "test_8_Keterangan", "rerun": "0"}, "8": {"status": "FAIL", "message": "           ConnectionRefusedError: [Errno 61] Connection refused\n       urllib3.exceptions.NewConnectionError: <urllib3.connection.HTTPConnection object at 0x124c17ac0>: Failed to establish a new connection: [Errno 61] Connection refused\n       urllib3.exceptions.MaxRetryError: HTTPConnectionPool(host='localhost', port=59788): Max retries exceeded with url: /session/2a406696e0202d8c2092d8a018d93ad9/element (Caused by NewConnectionError('<urllib3.connection.HTTPConnection object at 0x124c17ac0>: Failed to establish a new connection: [Errno 61] Connection refused'))\n           ConnectionRefusedError: [Errno 61] Connection refused\n       urllib3.exceptions.NewConnectionError: <urllib3.connection.HTTPConnection object at 0x1247a8c40>: Failed to establish a new connection: [Errno 61] Connection refused\n       urllib3.exceptions.MaxRetryError: HTTPConnectionPool(host='localhost', port=59788): Max retries exceeded with url: /session/2a406696e0202d8c2092d8a018d93ad9/screenshot (Caused by NewConnectionError('<urllib3.connection.HTTPConnection object at 0x1247a8c40>: Failed to establish a new connection: [Errno 61] Connection refused'))\n", "test_name": "test_9_ClickButtonSimpan", "rerun": "0"}, "9": {"status": "PASS", "message": "", "test_name": "test_10_SetupOs", "rerun": "0"}, "10": {"status": "PASS", "message": "", "test_name": "test_11_LoginSPV", "rerun": "0"}}, "suite_name": "4LaporanBulanan/10.Laporan7E/Fungsional/test_Laporan7E.py"}}}, "date": "April 22, 2023", "start_time": 1682134659.519232, "total_suite": 1, "status": "FAIL", "status_list": {"pass": "6", "fail": "5", "skip": "0", "error": "0", "xpass": "0", "xfail": "0", "rerun": "0"}, "total_tests": "11"}