{"content": {"suites": {"0": {"status": {"total_pass": 4, "total_skip": 0, "total_xpass": 0, "total_xfail": 0, "total_rerun": 0, "total_fail": 5, "total_error": 0}, "tests": {"0": {"status": "PASS", "message": "", "test_name": "test_1_SetupOs", "rerun": "0"}, "1": {"status": "PASS", "message": "", "test_name": "test_2_Login", "rerun": "0"}, "2": {"status": "PASS", "message": "", "test_name": "test_2_AksesMenu", "rerun": "0"}, "3": {"status": "FAIL", "message": "   selenium.common.exceptions.TimeoutException: Message: \n   Stacktrace:\n   0   chromedriver                        0x00000001044ccae8 chromedriver + 4958952\n   1   chromedriver                        0x00000001044c47b3 chromedriver + 4925363\n   2   chromedriver                        0x00000001040861d6 chromedriver + 475606\n   3   chromedriver                        0x00000001040c9a20 chromedriver + 752160\n   4   chromedriver                        0x00000001040c9c81 chromedriver + 752769\n   5   chromedriver                        0x000000010410df64 chromedriver + 1032036\n   6   chromedriver                        0x00000001040efc3d chromedriver + 908349\n   7   chromedriver                        0x000000010410b25b chromedriver + 1020507\n   8   chromedriver                        0x00000001040ef9e3 chromedriver + 907747\n   9   chromedriver                        0x00000001040b9aef chromedriver + 686831\n   10  chromedriver                        0x00000001040bb00e chromedriver + 692238\n   11  chromedriver                        0x00000001044889ad chromedriver + 4680109\n   12  chromedriver                        0x000000010448dc12 chromedriver + 4701202\n   13  chromedriver                        0x000000010449479f chromedriver + 4728735\n   14  chromedriver                        0x000000010448eb7a chromedriver + 4705146\n   15  chromedriver                        0x000000010446127e chromedriver + 4518526\n   16  chromedriver                        0x00000001044ae908 chromedriver + 4835592\n   17  chromedriver                        0x00000001044aea87 chromedriver + 4835975\n   18  chromedriver                        0x00000001044be00f chromedriver + 4898831\n   19  libsystem_pthread.dylib             0x00007ff8173931d3 _pthread_start + 125\n   20  libsystem_pthread.dylib             0x00007ff81738ebd3 thread_start + 15\n", "test_name": "test_3_CreateButton", "rerun": "0"}, "4": {"status": "PASS", "message": "", "test_name": "test_3_SearchWBP", "rerun": "0"}, "5": {"status": "FAIL", "message": "           ConnectionRefusedError: [Errno 61] Connection refused\n       urllib3.exceptions.NewConnectionError: <urllib3.connection.HTTPConnection object at 0x11c646910>: Failed to establish a new connection: [Errno 61] Connection refused\n       urllib3.exceptions.MaxRetryError: HTTPConnectionPool(host='localhost', port=61653): Max retries exceeded with url: /session/c27eaa387a6910293cd38dba7271030f/timeouts (Caused by NewConnectionError('<urllib3.connection.HTTPConnection object at 0x11c646910>: Failed to establish a new connection: [Errno 61] Connection refused'))\n", "test_name": "test_4_PilihJenisGangguan", "rerun": "0"}, "6": {"status": "FAIL", "message": "           ConnectionRefusedError: [Errno 61] Connection refused\n       urllib3.exceptions.NewConnectionError: <urllib3.connection.HTTPConnection object at 0x11d17f7c0>: Failed to establish a new connection: [Errno 61] Connection refused\n       urllib3.exceptions.MaxRetryError: HTTPConnectionPool(host='localhost', port=61653): Max retries exceeded with url: /session/c27eaa387a6910293cd38dba7271030f/timeouts (Caused by NewConnectionError('<urllib3.connection.HTTPConnection object at 0x11d17f7c0>: Failed to establish a new connection: [Errno 61] Connection refused'))\n", "test_name": "test_5_ClickButtonDaftarkan", "rerun": "0"}, "7": {"status": "FAIL", "message": "           ConnectionRefusedError: [Errno 61] Connection refused\n       urllib3.exceptions.NewConnectionError: <urllib3.connection.HTTPConnection object at 0x11c24d820>: Failed to establish a new connection: [Errno 61] Connection refused\n       urllib3.exceptions.MaxRetryError: HTTPConnectionPool(host='localhost', port=61653): Max retries exceeded with url: /session/c27eaa387a6910293cd38dba7271030f/timeouts (Caused by NewConnectionError('<urllib3.connection.HTTPConnection object at 0x11c24d820>: Failed to establish a new connection: [Errno 61] Connection refused'))\n", "test_name": "test_6_InputData", "rerun": "0"}, "8": {"status": "FAIL", "message": "           ConnectionRefusedError: [Errno 61] Connection refused\n       urllib3.exceptions.NewConnectionError: <urllib3.connection.HTTPConnection object at 0x11d0a1190>: Failed to establish a new connection: [Errno 61] Connection refused\n       urllib3.exceptions.MaxRetryError: HTTPConnectionPool(host='localhost', port=61653): Max retries exceeded with url: /session/c27eaa387a6910293cd38dba7271030f/window (Caused by NewConnectionError('<urllib3.connection.HTTPConnection object at 0x11d0a1190>: Failed to establish a new connection: [Errno 61] Connection refused'))\n", "test_name": "test_29_exit", "rerun": "0"}}, "suite_name": "4LaporanBulanan/10.Laporan7D/Fungsional/test_Laporan7D.py"}}}, "date": "April 14, 2023", "start_time": 1681473176.945614, "total_suite": 1, "status": "FAIL", "status_list": {"pass": "4", "fail": "5", "skip": "0", "error": "0", "xpass": "0", "xfail": "0", "rerun": "0"}, "total_tests": "9"}