{"content": {"suites": {"0": {"status": {"total_pass": 6, "total_skip": 0, "total_xpass": 0, "total_xfail": 0, "total_rerun": 0, "total_fail": 3, "total_error": 0}, "tests": {"0": {"status": "PASS", "message": "", "test_name": "test_1_SetupOs", "rerun": "0"}, "1": {"status": "PASS", "message": "", "test_name": "test_2_Login", "rerun": "0"}, "2": {"status": "PASS", "message": "", "test_name": "test_2_AksesMenu", "rerun": "0"}, "3": {"status": "PASS", "message": "", "test_name": "test_3_CreateButton", "rerun": "0"}, "4": {"status": "PASS", "message": "", "test_name": "test_3_SearchWBP", "rerun": "0"}, "5": {"status": "PASS", "message": "", "test_name": "test_4_PilihJenisGangguan", "rerun": "0"}, "6": {"status": "FAIL", "message": "           ConnectionRefusedError: [Errno 61] Connection refused\n       urllib3.exceptions.NewConnectionError: <urllib3.connection.HTTPConnection object at 0x112c422e0>: Failed to establish a new connection: [Errno 61] Connection refused\n       urllib3.exceptions.MaxRetryError: HTTPConnectionPool(host='localhost', port=56442): Max retries exceeded with url: /session/1569cf4eba7a071c7a04871e4d870260/timeouts (Caused by NewConnectionError('<urllib3.connection.HTTPConnection object at 0x112c422e0>: Failed to establish a new connection: [Errno 61] Connection refused'))\n", "test_name": "test_5_ClickButtonDaftarkan", "rerun": "0"}, "7": {"status": "FAIL", "message": "           ConnectionRefusedError: [Errno 61] Connection refused\n       urllib3.exceptions.NewConnectionError: <urllib3.connection.HTTPConnection object at 0x13095b400>: Failed to establish a new connection: [Errno 61] Connection refused\n       urllib3.exceptions.MaxRetryError: HTTPConnectionPool(host='localhost', port=56442): Max retries exceeded with url: /session/1569cf4eba7a071c7a04871e4d870260/timeouts (Caused by NewConnectionError('<urllib3.connection.HTTPConnection object at 0x13095b400>: Failed to establish a new connection: [Errno 61] Connection refused'))\n", "test_name": "test_6_InputData", "rerun": "0"}, "8": {"status": "FAIL", "message": "           ConnectionRefusedError: [Errno 61] Connection refused\n       urllib3.exceptions.NewConnectionError: <urllib3.connection.HTTPConnection object at 0x13094c2e0>: Failed to establish a new connection: [Errno 61] Connection refused\n       urllib3.exceptions.MaxRetryError: HTTPConnectionPool(host='localhost', port=56442): Max retries exceeded with url: /session/1569cf4eba7a071c7a04871e4d870260/element (Caused by NewConnectionError('<urllib3.connection.HTTPConnection object at 0x13094c2e0>: Failed to establish a new connection: [Errno 61] Connection refused'))\n", "test_name": "test_7_submit", "rerun": "0"}}, "suite_name": "4LaporanBulanan/10.Laporan7D/Fungsional/test_Laporan7D.py"}}}, "date": "April 17, 2023", "start_time": 1681708416.0313432, "total_suite": 1, "status": "FAIL", "status_list": {"pass": "6", "fail": "3", "skip": "0", "error": "0", "xpass": "0", "xfail": "0", "rerun": "0"}, "total_tests": "9"}