{"content": {"suites": {"0": {"status": {"total_pass": 3, "total_skip": 0, "total_xpass": 0, "total_xfail": 0, "total_rerun": 0, "total_fail": 4, "total_error": 0}, "tests": {"0": {"status": "PASS", "message": "", "test_name": "test_1_SetupOs", "rerun": "0"}, "1": {"status": "PASS", "message": "", "test_name": "test_2_Login", "rerun": "0"}, "2": {"status": "PASS", "message": "", "test_name": "test_2_AksesMenu", "rerun": "0"}, "3": {"status": "FAIL", "message": "       AttributeError: module 'selenium.webdriver.support.expected_conditions' has no attribute 'element_to_be_\u00e7\u00e7clickable'\n       assert False\n", "test_name": "test_3_CreateButton", "rerun": "0"}, "4": {"status": "FAIL", "message": "           ConnectionRefusedError: [Errno 61] Connection refused\n       urllib3.exceptions.NewConnectionError: <urllib3.connection.HTTPConnection object at 0x126aef1c0>: Failed to establish a new connection: [Errno 61] Connection refused\n       urllib3.exceptions.MaxRetryError: HTTPConnectionPool(host='localhost', port=64717): Max retries exceeded with url: /session/bffb422d6806bef3813a80dad75ee931/timeouts (Caused by NewConnectionError('<urllib3.connection.HTTPConnection object at 0x126aef1c0>: Failed to establish a new connection: [Errno 61] Connection refused'))\n", "test_name": "test_3_SearchWBP", "rerun": "0"}, "5": {"status": "FAIL", "message": "           ConnectionRefusedError: [Errno 61] Connection refused\n       urllib3.exceptions.NewConnectionError: <urllib3.connection.HTTPConnection object at 0x126f43130>: Failed to establish a new connection: [Errno 61] Connection refused\n       urllib3.exceptions.MaxRetryError: HTTPConnectionPool(host='localhost', port=64717): Max retries exceeded with url: /session/bffb422d6806bef3813a80dad75ee931/timeouts (Caused by NewConnectionError('<urllib3.connection.HTTPConnection object at 0x126f43130>: Failed to establish a new connection: [Errno 61] Connection refused'))\n", "test_name": "test_4_PilihJenisGangguan", "rerun": "0"}, "6": {"status": "FAIL", "message": "           ConnectionRefusedError: [Errno 61] Connection refused\n       urllib3.exceptions.NewConnectionError: <urllib3.connection.HTTPConnection object at 0x126f244f0>: Failed to establish a new connection: [Errno 61] Connection refused\n       urllib3.exceptions.MaxRetryError: HTTPConnectionPool(host='localhost', port=64717): Max retries exceeded with url: /session/bffb422d6806bef3813a80dad75ee931/window (Caused by NewConnectionError('<urllib3.connection.HTTPConnection object at 0x126f244f0>: Failed to establish a new connection: [Errno 61] Connection refused'))\n", "test_name": "test_29_exit", "rerun": "0"}}, "suite_name": "4LaporanBulanan/10.Laporan7D/Fungsional/test_Laporan7D.py"}}}, "date": "April 13, 2023", "start_time": 1681405030.2904189, "total_suite": 1, "status": "FAIL", "status_list": {"pass": "3", "fail": "4", "skip": "0", "error": "0", "xpass": "0", "xfail": "0", "rerun": "0"}, "total_tests": "7"}