{"content": {"suites": {"0": {"status": {"total_pass": 1, "total_skip": 0, "total_xpass": 0, "total_xfail": 0, "total_rerun": 0, "total_fail": 5, "total_error": 0}, "tests": {"0": {"status": "PASS", "message": "", "test_name": "test_1_SetupOS", "rerun": "0"}, "1": {"status": "FAIL", "message": "       http.client.RemoteDisconnected: Remote end closed connection without response\n       urllib3.exceptions.ProtocolError: ('Connection aborted.', RemoteDisconnected('Remote end closed connection without response'))\n", "test_name": "test_2_Login", "rerun": "0"}, "2": {"status": "FAIL", "message": "           ConnectionRefusedError: [Errno 61] Connection refused\n       urllib3.exceptions.NewConnectionError: <urllib3.connection.HTTPConnection object at 0x117a3bee0>: Failed to establish a new connection: [Errno 61] Connection refused\n       urllib3.exceptions.MaxRetryError: HTTPConnectionPool(host='localhost', port=55786): Max retries exceeded with url: /session/4e27fa539bab66f5f27883834c62b28c/timeouts (Caused by NewConnectionError('<urllib3.connection.HTTPConnection object at 0x117a3bee0>: Failed to establish a new connection: [Errno 61] Connection refused'))\n", "test_name": "test_3_Akses_menu", "rerun": "0"}, "3": {"status": "FAIL", "message": "           ConnectionRefusedError: [Errno 61] Connection refused\n       urllib3.exceptions.NewConnectionError: <urllib3.connection.HTTPConnection object at 0x11783a490>: Failed to establish a new connection: [Errno 61] Connection refused\n       urllib3.exceptions.MaxRetryError: HTTPConnectionPool(host='localhost', port=55786): Max retries exceeded with url: /session/4e27fa539bab66f5f27883834c62b28c/timeouts (Caused by NewConnectionError('<urllib3.connection.HTTPConnection object at 0x11783a490>: Failed to establish a new connection: [Errno 61] Connection refused'))\n", "test_name": "test_4_ButtonTambah_PegawaiTambah", "rerun": "0"}, "4": {"status": "FAIL", "message": "           ConnectionRefusedError: [Errno 61] Connection refused\n       urllib3.exceptions.NewConnectionError: <urllib3.connection.HTTPConnection object at 0x117b3d850>: Failed to establish a new connection: [Errno 61] Connection refused\n       urllib3.exceptions.MaxRetryError: HTTPConnectionPool(host='localhost', port=55786): Max retries exceeded with url: /session/4e27fa539bab66f5f27883834c62b28c/timeouts (Caused by NewConnectionError('<urllib3.connection.HTTPConnection object at 0x117b3d850>: Failed to establish a new connection: [Errno 61] Connection refused'))\n", "test_name": "test_5_Input", "rerun": "0"}, "5": {"status": "FAIL", "message": "           ConnectionRefusedError: [Errno 61] Connection refused\n       urllib3.exceptions.NewConnectionError: <urllib3.connection.HTTPConnection object at 0x117aa1ca0>: Failed to establish a new connection: [Errno 61] Connection refused\n       urllib3.exceptions.MaxRetryError: HTTPConnectionPool(host='localhost', port=55786): Max retries exceeded with url: /session/4e27fa539bab66f5f27883834c62b28c/window (Caused by NewConnectionError('<urllib3.connection.HTTPConnection object at 0x117aa1ca0>: Failed to establish a new connection: [Errno 61] Connection refused'))\n", "test_name": "test_exit", "rerun": "0"}}, "suite_name": "test_2Fungsi_P2U_ManualTambah.py"}}}, "date": "December 03, 2022", "start_time": 1670052424.544277, "total_suite": 1, "status": "FAIL", "status_list": {"pass": "1", "fail": "5", "skip": "0", "error": "0", "xpass": "0", "xfail": "0", "rerun": "0"}, "total_tests": "6"}